'date'

Traceback (most recent call last):
  File "/opt/hostedtoolcache/Python/3.8.6/x64/lib/python3.8/site-packages/pandas/core/indexes/base.py", line 2898, in get_loc
    return self._engine.get_loc(casted_key)
  File "pandas/_libs/index.pyx", line 70, in pandas._libs.index.IndexEngine.get_loc
  File "pandas/_libs/index.pyx", line 101, in pandas._libs.index.IndexEngine.get_loc
  File "pandas/_libs/hashtable_class_helper.pxi", line 1675, in pandas._libs.hashtable.PyObjectHashTable.get_item
  File "pandas/_libs/hashtable_class_helper.pxi", line 1683, in pandas._libs.hashtable.PyObjectHashTable.get_item
KeyError: 'date'

The above exception was the direct cause of the following exception:

Traceback (most recent call last):
  File "task.py", line 116, in main
    _run()
  File "task.py", line 107, in _run
    roller.download_remote_files()
  File "task.py", line 46, in download_remote_files
    self._cases = self._download_remote_excel_file('Cases and Deaths by County by Date')
  File "task.py", line 59, in _download_remote_excel_file
    df['date'] = df['date'].apply(lambda x: to_datetime(x).date())
  File "/opt/hostedtoolcache/Python/3.8.6/x64/lib/python3.8/site-packages/pandas/core/frame.py", line 2906, in __getitem__
    indexer = self.columns.get_loc(key)
  File "/opt/hostedtoolcache/Python/3.8.6/x64/lib/python3.8/site-packages/pandas/core/indexes/base.py", line 2900, in get_loc
    raise KeyError(key) from err
KeyError: 'date'
